Workbook

Sheet Instructions 
B4: Instructions for Completing the ACSA Functional and Non-Functional Requirements Assessment - Testing Phase
B6: This assessment is designed to help countries and solution providers objectively evaluate the extent to which an existing or proposed CRVS, Legal Identity, or related digital solution meets the ACSA requirements catalogue. The assessment should be evidence-based and completed collaboratively by functional, technical, and implementation teams. Responses should reflect the current capabilities of the solution, rather than planned future functionality, unless specifically stated.
B8: How to Complete the Assessment
B10: 1. Review each requirement carefully and assess the solution against the stated requirement.
B11: 2. Select the appropriate Level of Compliance:
B12: Fully Meets – The requirement is available and supported out of the box.
B13: Meets through Configuration – The requirement can be enabled through configuration without software development.
B14: Customization Required – Additional development or significant configuration is required.
B15: Not Available – The requirement is not supported.
B16: 3. Indicate the operating mode:
B17: Online
B18: Offline
... B28: The objective is not merely to achieve a high score, but to identify strengths, gaps, customization needs, interoperability dependencies, and areas for future investment and improvement.

Sheet Master Requirements Catalogue
A1: ACSA Core Requirements Screening Questionnaire
A3: System Details
A4: Name of the software/country
A5: Contact Person's Name
A6: Contact Person's Email
A7: Contact Person's Phone Number
A9: Screening Questionnaire
A10: PLEASE DO NOT TOUCH ENTRIES IN THE BELOW COLUMNS | G10: ENTER YOUR RESPONSES IN BELOW COLUMNS | K10: SCORES
A12: ID | B12: Requirement Type | C12: Category | D12: Requirement Name | E12: Description | F12: Priority | G12: Level of compliance | H12: Online/Offline | I12: Dependent on other systems | J12: Dependent System(s) | K12: Score | L12: Weight | M12: Weighted Score
A13: ACSA-FR-UC01-REQ001 | B13: Functional | C13: Declaration | D13: Capture Declaration | E13: The system shall capture declarations for normal, late, and delayed registrations for vital events (birth, death, marriage and divorce). | F13: Must | K13: =IFERROR(VLOOKUP(G13,'Taxonomy Sheet'!$A$3:$C$6,2,FALSE),"") | L13: =IFERROR(VLOOKUP(F13,'Taxonomy Sheet'!$E$3:$F$5,2,FALSE),"") -> 2 | M13: =IF(OR(K13="",L13=""),"",K13*L13)
A14: ACSA-FR-UC01-REQ002 | B14: Functional | C14: Declaration | D14: Generate Declaration ID | E14: The system shall generate a unique Declaration ID for each declaration record. | F14: Must | K14: =IFERROR(VLOOKUP(G14,'Taxonomy Sheet'!$A$3:$C$6,2,FALSE),"") | L14: =IFERROR(VLOOKUP(F14,'Taxonomy Sheet'!$E$3:$F$5,2,FALSE),"") -> 2 | M14: =IF(OR(K14="",L14=""),"",K14*L14)
A15: ACSA-FR-UC01-REQ003 | B15: Functional | C15: Declaration | D15: Attach Evidence | E15: The system shall allow attaching or referencing supporting documents and attestations. | F15: Must | K15: =IFERROR(VLOOKUP(G15,'Taxonomy Sheet'!$A$3:$C$6,2,FALSE),"") | L15: =IFERROR(VLOOKUP(F15,'Taxonomy Sheet'!$E$3:$F$5,2,FALSE),"") -> 2 | M15: =IF(OR(K15="",L15=""),"",K15*L15)
A16: ACSA-FR-UC01-REQ004 | B16: Functional | C16: Declaration | D16: Declaration-to-Registration Linkage | E16: The system shall support linkage between a declaration and the subsequent registration record. | F16: Must | K16: =IFERROR(VLOOKUP(G16,'Taxonomy Sheet'!$A$3:$C$6,2,FALSE),"") | L16: =IFERROR(VLOOKUP(F16,'Taxonomy Sheet'!$E$3:$F$5,2,FALSE),"") -> 2 | M16: =IF(OR(K16="",L16=""),"",K16*L16)
A17: ACSA-FR-UC01-REQ005 | B17: Functional | C17: Declaration | D17: Support Multiple Channels | E17: The system shall support multiple declaration models (facility-assisted, community, self-service portal, consular). | F17: Must | K17: =IFERROR(VLOOKUP(G17,'Taxonomy Sheet'!$A$3:$C$6,2,FALSE),"") | L17: =IFERROR(VLOOKUP(F17,'Taxonomy Sheet'!$E$3:$F$5,2,FALSE),"") -> 2 | M17: =IF(OR(K17="",L17=""),"",K17*L17)
A18: ACSA-FR-UC01-REQ006 | B18: Functional | C18: Declaration | D18: Notification Retrieval | E18: The system shall retrieve notification information using a notification number where available. | F18: Must | K18: =IFERROR(VLOOKUP(G18,'Taxonomy Sheet'!$A$3:$C$6,2,FALSE),"") | L18: =IFERROR(VLOOKUP(F18,'Taxonomy Sheet'!$E$3:$F$5,2,FALSE),"") -> 2 | M18: =IF(OR(K18="",L18=""),"",K18*L18)
A19: ACSA-FR-UC01-REQ007 | B19: Functional | C19: Declaration | D19: Validation | E19: The system shall validate mandatory fields and logical consistency before accepting a declaration. | F19: Must | K19: =IFERROR(VLOOKUP(G19,'Taxonomy Sheet'!$A$3:$C$6,2,FALSE),"") | L19: =IFERROR(VLOOKUP(F19,'Taxonomy Sheet'!$E$3:$F$5,2,FALSE),"") -> 2 | M19: =IF(OR(K19="",L19=""),"",K19*L19)
A20: ACSA-FR-UC01-REQ008 | B20: Functional | C20: Declaration | D20: Acknowledge Submission | E20: The system shall issue an acknowledgement slip, SMS, email, or tracking receipt to the declarant. | F20: Must | K20: =IFERROR(VLOOKUP(G20,'Taxonomy Sheet'!$A$3:$C$6,2,FALSE),"") | L20: =IFERROR(VLOOKUP(F20,'Taxonomy Sheet'!$E$3:$F$5,2,FALSE),"") -> 2 | M20: =IF(OR(K20="",L20=""),"",K20*L20)
A21: ACSA-FR-UC01-REQ009 | B21: Functional | C21: Declaration | D21: Audit Trail | E21: The system shall maintain an audit trail for the user, channel, time of submission, and any subsequent edits or escalations. | F21: Must | K21: =IFERROR(VLOOKUP(G21,'Taxonomy Sheet'!$A$3:$C$6,2,FALSE),"") | L21: =IFERROR(VLOOKUP(F21,'Taxonomy Sheet'!$E$3:$F$5,2,FALSE),"") -> 2 | M21: =IF(OR(K21="",L21=""),"",K21*L21)
A22: ACSA-FR-UC01-REQ010 | B22: Functional | C22: Declaration | D22: Deduplication | E22: The system shall automatically detect and alert users to duplicate records and provide options for merging, invalidating, or dismissing records. | F22: Must | K22: =IFERROR(VLOOKUP(G22,'Taxonomy Sheet'!$A$3:$C$6,2,FALSE),"") | L22: =IFERROR(VLOOKUP(F22,'Taxonomy Sheet'!$E$3:$F$5,2,FALSE),"") -> 2 | M22: =IF(OR(K22="",L22=""),"",K22*L22)
A23: ACSA-FR-UC02-REQ001 | B23: Functional | C23: Registration | D23: Create Legal Record | E23: The system shall create the official legal civil registration record after declaration review and verification. | F23: Must | K23: =IFERROR(VLOOKUP(G23,'Taxonomy Sheet'!$A$3:$C$6,2,FALSE),"") | L23: =IFERROR(VLOOKUP(F23,'Taxonomy Sheet'!$E$3:$F$5,2,FALSE),"") -> 2 | M23: =IF(OR(K23="",L23=""),"",K23*L23)
A24: ACSA-FR-UC02-REQ002 | B24: Functional | C24: Registration | D24: Generate Registration ID | E24: The system shall generate a unique Registration ID for the official record linking it to the declaration ID. | F24: Must | K24: =IFERROR(VLOOKUP(G24,'Taxonomy Sheet'!$A$3:$C$6,2,FALSE),"") | L24: =IFERROR(VLOOKUP(F24,'Taxonomy Sheet'!$E$3:$F$5,2,FALSE),"") -> 2 | M24: =IF(OR(K24="",L24=""),"",K24*L24)
... A64: ACSA-FR-UC08-REQ006 | B64: Functional | C64: Vital Statistics | D64: Data Quality Checks | E64: The system shall enable capture, update, and processing of a declaration using devices without internet connectivity. | F64: Could | K64: =IFERROR(VLOOKUP(G64,'Taxonomy Sheet'!$A$3:$C$6,2,FALSE),"") | L64: =IFERROR(VLOOKUP(F64,'Taxonomy Sheet'!$E$3:$F$5,2,FALSE),"") -> 1 | M64: =IF(OR(K64="",L64=""),"",K64*L64)
A65: ACSA-FR-UC09-REQ001 | B65: Functional | C65: Mobile & Offline | D65: Offline Capture | F65: Should | K65: =IFERROR(VLOOKUP(G65,'Taxonomy Sheet'!$A$3:$C$6,2,FALSE),"") | L65: =IFERROR(VLOOKUP(F65,'Taxonomy Sheet'!$E$3:$F$5,2,FALSE),"") -> 1.5 | M65: =IF(OR(K65="",L65=""),"",K65*L65)
A66: ACSA-FR-UC09-REQ002 | B66: Functional | C66: Mobile & Offline | D66: Secure Local Storage | E66: The system shall encrypt offline data at rest on the device and make it accessible only to authorized users. | F66: Should | K66: =IFERROR(VLOOKUP(G66,'Taxonomy Sheet'!$A$3:$C$6,2,FALSE),"") | L66: =IFERROR(VLOOKUP(F66,'Taxonomy Sheet'!$E$3:$F$5,2,FALSE),"") -> 1.5 | M66: =IF(OR(K66="",L66=""),"",K66*L66)
A67: ACSA-FR-UC09-REQ003 | B67: Functional | C67: Mobile & Offline | D67: Data Synchronization | E67: The system shall synchronize offline records with the central CRVS database once connectivity is restored. | F67: Should | K67: =IFERROR(VLOOKUP(G67,'Taxonomy Sheet'!$A$3:$C$6,2,FALSE),"") | L67: =IFERROR(VLOOKUP(F67,'Taxonomy Sheet'!$E$3:$F$5,2,FALSE),"") -> 1.5 | M67: =IF(OR(K67="",L67=""),"",K67*L67)
A68: ACSA-FR-UC09-REQ004 | B68: Functional | C68: Mobile & Offline | D68: Conflict Resolution | E68: The system shall apply duplicate detection and conflict resolution when records are uploaded from offline devices. | F68: Should | K68: =IFERROR(VLOOKUP(G68,'Taxonomy Sheet'!$A$3:$C$6,2,FALSE),"") | L68: =IFERROR(VLOOKUP(F68,'Taxonomy Sheet'!$E$3:$F$5,2,FALSE),"") -> 1.5 | M68: =IF(OR(K68="",L68=""),"",K68*L68)
A69: ACSA-FR-UC09-REQ005 | B69: Functional | C69: Mobile & Offline | D69: Audit Traceability | E69: The system shall maintain an audit trail from device capture to central synchronization (device ID, user ID, timestamps). | F69: Should | K69: =IFERROR(VLOOKUP(G69,'Taxonomy Sheet'!$A$3:$C$6,2,FALSE),"") | L69: =IFERROR(VLOOKUP(F69,'Taxonomy Sheet'!$E$3:$F$5,2,FALSE),"") -> 1.5 | M69: =IF(OR(K69="",L69=""),"",K69*L69)
A70: ACSA-FR-UC09-REQ006 | B70: Functional | C70: Mobile & Offline | D70: Offline Authentication | E70: The system shall support secure offline authentication using cached credentials or another approved mechanism. | F70: Should | K70: =IFERROR(VLOOKUP(G70,'Taxonomy Sheet'!$A$3:$C$6,2,FALSE),"") | L70: =IFERROR(VLOOKUP(F70,'Taxonomy Sheet'!$E$3:$F$5,2,FALSE),"") -> 1.5 | M70: =IF(OR(K70="",L70=""),"",K70*L70)
A71: ACSA-FR-UC09-REQ007 | B71: Functional | C71: Mobile & Offline | D71: Offline Identifier Reconciliation | E71: The system shall reconcile temporary or preallocated offline identifiers with official central identifiers after synchronization. | F71: Should | K71: =IFERROR(VLOOKUP(G71,'Taxonomy Sheet'!$A$3:$C$6,2,FALSE),"") | L71: =IFERROR(VLOOKUP(F71,'Taxonomy Sheet'!$E$3:$F$5,2,FALSE),"") -> 1.5 | M71: =IF(OR(K71="",L71=""),"",K71*L71)
A72: ACSA-FR-UC10-REQ001 | B72: Functional | C72: Authentication & Certificate Verification | D72: Provide Verification Service | E72: The system shall provide a secure service to verify civil registration certificates and underlying event records through a verifiable credentials platform (if available) – the CRVS system should not try to re-create such a platform. | F72: Must | K72: =IFERROR(VLOOKUP(G72,'Taxonomy Sheet'!$A$3:$C$6,2,FALSE),"") | L72: =IFERROR(VLOOKUP(F72,'Taxonomy Sheet'!$E$3:$F$5,2,FALSE),"") -> 2 | M72: =IF(OR(K72="",L72=""),"",K72*L72)
A73: ACSA-FR-UC10-REQ002 | B73: Functional | C73: Authentication & Certificate Verification | D73: Support Multiple Channels | E73: The system shall support multiple verification channels: online portal, QR/barcode scan, API, and offline verification. | F73: Should | K73: =IFERROR(VLOOKUP(G73,'Taxonomy Sheet'!$A$3:$C$6,2,FALSE),"") | L73: =IFERROR(VLOOKUP(F73,'Taxonomy Sheet'!$E$3:$F$5,2,FALSE),"") -> 1.5 | M73: =IF(OR(K73="",L73=""),"",K73*L73)
A74: ACSA-FR-UC10-REQ003 | B74: Functional | C74: Authentication & Certificate Verification | D74: Enforce Access Control | E74: The system shall enforce differentiated access levels (public vs. restricted) based on legal frameworks and user credentials. | F74: Should | K74: =IFERROR(VLOOKUP(G74,'Taxonomy Sheet'!$A$3:$C$6,2,FALSE),"") | L74: =IFERROR(VLOOKUP(F74,'Taxonomy Sheet'!$E$3:$F$5,2,FALSE),"") -> 1.5 | M74: =IF(OR(K74="",L74=""),"",K74*L74)
A75: ACSA-FR-UC10-REQ004 | B75: Functional | C75: Authentication & Certificate Verification | D75: Maintain Audit Log | E75: The system shall maintain a complete audit trail of all verification attempts, including user, channel, and timestamp. | F75: Should | K75: =IFERROR(VLOOKUP(G75,'Taxonomy Sheet'!$A$3:$C$6,2,FALSE),"") | L75: =IFERROR(VLOOKUP(F75,'Taxonomy Sheet'!$E$3:$F$5,2,FALSE),"") -> 1.5 | M75: =IF(OR(K75="",L75=""),"",K75*L75)
A76: ACSA-FR-UC10-REQ005 | B76: Functional | C76: Authentication & Certificate Verification | D76: Differentiated Verification Responses | E76: The system shall support differentiated verification responses, ranging from yes/no confirmation to full legal verification according to user authorization and legal rules. | F76: Should | K76: =IFERROR(VLOOKUP(G76,'Taxonomy Sheet'!$A$3:$C$6,2,FALSE),"") | L76: =IFERROR(VLOOKUP(F76,'Taxonomy Sheet'!$E$3:$F$5,2,FALSE),"") -> 1.5 | M76: =IF(OR(K76="",L76=""),"",K76*L76)
A77: ACSA-FR-UC11-REQ001 | B77: Functional | C77: Duplication Management | D77: Detect Duplicates | E77: The system shall detect and prevent duplicate registrations using scheduled or event-based matching algorithms. | F77: Must | K77: =IFERROR(VLOOKUP(G77,'Taxonomy Sheet'!$A$3:$C$6,2,FALSE),"") | L77: =IFERROR(VLOOKUP(F77,'Taxonomy Sheet'!$E$3:$F$5,2,FALSE),"") -> 2 | M77: =IF(OR(K77="",L77=""),"",K77*L77)
... A220: ACSA-NFR-QUAL-REQ016 | B220: Non-functional | C220: Quality / Operations | D220: Incident and DR Testing | E220: The system shall support documented incident response procedures, regular vulnerability scans, penetration testing, and annual testing of incident response and disaster recovery procedures. | F220: Should | K220: =IFERROR(VLOOKUP(G220,'Taxonomy Sheet'!$A$3:$C$6,2,FALSE),"") | L220: =IFERROR(VLOOKUP(F220,'Taxonomy Sheet'!$E$3:$F$5,2,FALSE),"") -> 1.5 | M220: =IF(OR(K220="",L220=""),"",K220*L220)
K221: =IFERROR(VLOOKUP(G221,'Taxonomy Sheet'!$A$3:$C$6,2,FALSE),"") | L221: =IFERROR(VLOOKUP(F221,'Taxonomy Sheet'!$E$3:$F$5,2,FALSE),"") | M221: =IF(OR(K221="",L221=""),"",K221*L221)
K222: =IFERROR(VLOOKUP(G222,'Taxonomy Sheet'!$A$3:$C$6,2,FALSE),"") | L222: =IFERROR(VLOOKUP(F222,'Taxonomy Sheet'!$E$3:$F$5,2,FALSE),"") | M222: =IF(OR(K222="",L222=""),"",K222*L222)
K223: =IFERROR(VLOOKUP(G223,'Taxonomy Sheet'!$A$3:$C$6,2,FALSE),"") | L223: =IFERROR(VLOOKUP(F223,'Taxonomy Sheet'!$E$3:$F$5,2,FALSE),"") | M223: =IF(OR(K223="",L223=""),"",K223*L223)
K224: =IFERROR(VLOOKUP(G224,'Taxonomy Sheet'!$A$3:$C$6,2,FALSE),"") | L224: =IFERROR(VLOOKUP(F224,'Taxonomy Sheet'!$E$3:$F$5,2,FALSE),"") | M224: =IF(OR(K224="",L224=""),"",K224*L224)
...

Sheet Catalogue Summary
A1: Metric | B1: Value
A2: Total requirements | B2: 207
A3: Functional requirements | B3: 129
A4: Non-functional requirements | B4: 78

Sheet Taxonomy Sheet
A1: Table 1 - Level of Compliance in ACSA | E1: Table 2 - Weights | H1: Table 3 - Online/Offline | J1: Table 4 - Dependency on Other Systems
A2: Category | B2: Description | C2: Score | E2: Category | F2: Score | H2: Category | J2: Category
A3: Fully Meets | B3: Fully supported standard functionality. Functional and technical requirements are met directly by the proposed CRVS solution without any additional configuration, customization, or development. | C3: 2 | E3: Must | F3: 2 | H3: Online | J3: Yes
A4: Meets through Configuration | B4: Fully supported through configuration. Requirements are not met directly in the standard setup but can be achieved using built-in configuration tools, parameters, or minor adjustments. May require light to moderate technical effort, with limited or potential additional costs. | C4: 2 | E4: Should | F4: 1.5 | H4: Offline | J4: No
A5: Customization Required | B5: Requirements cannot be met through standard functionality or configuration. Additional development by a specialized programmer or technical consultant is required. The proposer should provide estimated effort (man-hours) and/or hourly rates. May involve integration with third-party systems. | C5: 1 | E5: Could | F5: 1 | H5: Both
A6: Not Available | B6: The requirement is not supported and is not planned for future development. It cannot be met through configuration or customization without relying on external or unavailable third-party solutions. | C6: 0

Sheet Analytics
A1: Table 1 - Weighted Scores
A2: Scope | B2: Metric | C2: Must | D2: Should | E2: Could | F2: Total | G2: Achievement %
A3: Total (Functional + Non-functional) | B3: Max Possible Score | C3: =COUNTIFS('Master Requirements Catalogue'!$A$13:$A$220,"<>",'Master Requirements Catalogue'!$F$13:$F$220,"Must")*3*2 -> 678 | D3: =COUNTIFS('Master Requirements Catalogue'!$A$13:$A$220,"<>",'Master Requirements Catalogue'!$F$13:$F$220,"Should")*3*1.5 -> 364.5 | E3: =COUNTIFS('Master Requirements Catalogue'!$A$13:$A$220,"<>",'Master Requirements Catalogue'!$F$13:$F$220,"Could")*3*1 -> 42 | F3: =SUM(C3:E3) -> 1084.5
A4: Total (Functional + Non-functional) | B4: Achieved Weighted Score | C4: =SUMIFS('Master Requirements Catalogue'!$M$13:$M$220,'Master Requirements Catalogue'!$A$13:$A$220,"<>",'Master Requirements Catalogue'!$F$13:$F$220,"Must") -> 0 | D4: =SUMIFS('Master Requirements Catalogue'!$M$13:$M$220,'Master Requirements Catalogue'!$A$13:$A$220,"<>",'Master Requirements Catalogue'!$F$13:$F$220,"Should") -> 0 | E4: =SUMIFS('Master Requirements Catalogue'!$M$13:$M$220,'Master Requirements Catalogue'!$A$13:$A$220,"<>",'Master Requirements Catalogue'!$F$13:$F$220,"Could") -> 0 | F4: =SUM(C4:E4) -> 0 | G4: =IFERROR(F4/F3,"") -> 0
A5: Functional | B5: Max Possible Score | C5: =COUNTIFS('Master Requirements Catalogue'!$A$13:$A$220,"<>",'Master Requirements Catalogue'!$B$13:$B$220,"Functional",'Master Requirements Catalogue'!$F$13:$F$220,"Must")*3*2 -> 432 | D5: =COUNTIFS('Master Requirements Catalogue'!$A$13:$A$220,"<>",'Master Requirements Catalogue'!$B$13:$B$220,"Functional",'Master Requirements Catalogue'!$F$13:$F$220,"Should")*3*1.5 -> 202.5 | E5: =COUNTIFS('Master Requirements Catalogue'!$A$13:$A$220,"<>",'Master Requirements Catalogue'!$B$13:$B$220,"Functional",'Master Requirements Catalogue'!$F$13:$F$220,"Could")*3*1 -> 39 | F5: =SUM(C5:E5) -> 673.5
A6: Functional | B6: Achieved Weighted Score | C6: =SUMIFS('Master Requirements Catalogue'!$M$13:$M$220,'Master Requirements Catalogue'!$A$13:$A$220,"<>",'Master Requirements Catalogue'!$B$13:$B$220,"Functional",'Master Requirements Catalogue'!$F$13:$F$220,"Must") -> 0 | D6: =SUMIFS('Master Requirements Catalogue'!$M$13:$M$220,'Master Requirements Catalogue'!$A$13:$A$220,"<>",'Master Requirements Catalogue'!$B$13:$B$220,"Functional",'Master Requirements Catalogue'!$F$13:$F$220,"Should") -> 0 | E6: =SUMIFS('Master Requirements Catalogue'!$M$13:$M$220,'Master Requirements Catalogue'!$A$13:$A$220,"<>",'Master Requirements Catalogue'!$B$13:$B$220,"Functional",'Master Requirements Catalogue'!$F$13:$F$220,"Could") -> 0 | F6: =SUM(C6:E6) -> 0 | G6: =IFERROR(F6/F5,"") -> 0
A7: Non-functional | B7: Max Possible Score | C7: =COUNTIFS('Master Requirements Catalogue'!$A$13:$A$220,"<>",'Master Requirements Catalogue'!$B$13:$B$220,"Non-functional",'Master Requirements Catalogue'!$F$13:$F$220,"Must")*3*2 -> 246 | D7: =COUNTIFS('Master Requirements Catalogue'!$A$13:$A$220,"<>",'Master Requirements Catalogue'!$B$13:$B$220,"Non-functional",'Master Requirements Catalogue'!$F$13:$F$220,"Should")*3*1.5 -> 162 | E7: =COUNTIFS('Master Requirements Catalogue'!$A$13:$A$220,"<>",'Master Requirements Catalogue'!$B$13:$B$220,"Non-functional",'Master Requirements Catalogue'!$F$13:$F$220,"Could")*3*1 -> 3 | F7: =SUM(C7:E7) -> 411
A8: Non-functional | B8: Achieved Weighted Score | C8: =SUMIFS('Master Requirements Catalogue'!$M$13:$M$220,'Master Requirements Catalogue'!$A$13:$A$220,"<>",'Master Requirements Catalogue'!$B$13:$B$220,"Non-functional",'Master Requirements Catalogue'!$F$13:$F$220,"Must") -> 0 | D8: =SUMIFS('Master Requirements Catalogue'!$M$13:$M$220,'Master Requirements Catalogue'!$A$13:$A$220,"<>",'Master Requirements Catalogue'!$B$13:$B$220,"Non-functional",'Master Requirements Catalogue'!$F$13:$F$220,"Should") -> 0 | E8: =SUMIFS('Master Requirements Catalogue'!$M$13:$M$220,'Master Requirements Catalogue'!$A$13:$A$220,"<>",'Master Requirements Catalogue'!$B$13:$B$220,"Non-functional",'Master Requirements Catalogue'!$F$13:$F$220,"Could") -> 0 | F8: =SUM(C8:E8) -> 0 | G8: =IFERROR(F8/F7,"") -> 0
A11: Table 2 - Level of Compliance by Total, Functional and Non-functional
A12: Scope | B12: Metric | C12: Fully Meets | D12: Meets through Configuration | E12: Customization Required | F12: Not Available | G12: No Response | H12: Total | I12: Response Rate %
A13: Total (Functional + Non-functional) | B13: Count | C13: =COUNTIFS('Master Requirements Catalogue'!$A$13:$A$220,"<>",'Master Requirements Catalogue'!$G$13:$G$220,"Fully Meets") -> 0 | D13: =COUNTIFS('Master Requirements Catalogue'!$A$13:$A$220,"<>",'Master Requirements Catalogue'!$G$13:$G$220,"Meets through Configuration") -> 0 | E13: =COUNTIFS('Master Requirements Catalogue'!$A$13:$A$220,"<>",'Master Requirements Catalogue'!$G$13:$G$220,"Customization Required") -> 0 | F13: =COUNTIFS('Master Requirements Catalogue'!$A$13:$A$220,"<>",'Master Requirements Catalogue'!$G$13:$G$220,"Not Available") -> 0 | G13: =COUNTIFS('Master Requirements Catalogue'!$A$13:$A$220,"<>",'Master Requirements Catalogue'!$G$13:$G$220,"") -> 208 | H13: =SUM(C13:G13) -> 208 | I13: =IFERROR(1-(G13/H13),"") -> 0
A14: Total (Functional + Non-functional) | B14: % | C14: =IFERROR(C13/$H13,"") -> 0 | D14: =IFERROR(D13/$H13,"") -> 0 | E14: =IFERROR(E13/$H13,"") -> 0 | F14: =IFERROR(F13/$H13,"") -> 0 | G14: =IFERROR(G13/$H13,"") -> 1 | H14: =SUM(C14:G14) -> 1 | I14: =I13 -> 0
A15: Functional | B15: Count | C15: =COUNTIFS('Master Requirements Catalogue'!$A$13:$A$220,"<>",'Master Requirements Catalogue'!$B$13:$B$220,"Functional",'Master Requirements Catalogue'!$G$13:$G$220,"Fully Meets") -> 0 | D15: =COUNTIFS('Master Requirements Catalogue'!$A$13:$A$220,"<>",'Master Requirements Catalogue'!$B$13:$B$220,"Functional",'Master Requirements Catalogue'!$G$13:$G$220,"Meets through Configuration") -> 0 | E15: =COUNTIFS('Master Requirements Catalogue'!$A$13:$A$220,"<>",'Master Requirements Catalogue'!$B$13:$B$220,"Functional",'Master Requirements Catalogue'!$G$13:$G$220,"Customization Required") -> 0 | F15: =COUNTIFS('Master Requirements Catalogue'!$A$13:$A$220,"<>",'Master Requirements Catalogue'!$B$13:$B$220,"Functional",'Master Requirements Catalogue'!$G$13:$G$220,"Not Available") -> 0 | G15: =COUNTIFS('Master Requirements Catalogue'!$A$13:$A$220,"<>",'Master Requirements Catalogue'!$B$13:$B$220,"Functional",'Master Requirements Catalogue'!$G$13:$G$220,"") -> 130 | H15: =SUM(C15:G15) -> 130 | I15: =IFERROR(1-(G15/H15),"") -> 0
A16: Functional | B16: % | C16: =IFERROR(C15/$H15,"") -> 0 | D16: =IFERROR(D15/$H15,"") -> 0 | E16: =IFERROR(E15/$H15,"") -> 0 | F16: =IFERROR(F15/$H15,"") -> 0 | G16: =IFERROR(G15/$H15,"") -> 1 | H16: =SUM(C16:G16) -> 1 | I16: =I15 -> 0
A17: Non-functional | B17: Count | C17: =COUNTIFS('Master Requirements Catalogue'!$A$13:$A$220,"<>",'Master Requirements Catalogue'!$B$13:$B$220,"Non-functional",'Master Requirements Catalogue'!$G$13:$G$220,"Fully Meets") -> 0 | D17: =COUNTIFS('Master Requirements Catalogue'!$A$13:$A$220,"<>",'Master Requirements Catalogue'!$B$13:$B$220,"Non-functional",'Master Requirements Catalogue'!$G$13:$G$220,"Meets through Configuration") -> 0 | E17: =COUNTIFS('Master Requirements Catalogue'!$A$13:$A$220,"<>",'Master Requirements Catalogue'!$B$13:$B$220,"Non-functional",'Master Requirements Catalogue'!$G$13:$G$220,"Customization Required") -> 0 | F17: =COUNTIFS('Master Requirements Catalogue'!$A$13:$A$220,"<>",'Master Requirements Catalogue'!$B$13:$B$220,"Non-functional",'Master Requirements Catalogue'!$G$13:$G$220,"Not Available") -> 0 | G17: =COUNTIFS('Master Requirements Catalogue'!$A$13:$A$220,"<>",'Master Requirements Catalogue'!$B$13:$B$220,"Non-functional",'Master Requirements Catalogue'!$G$13:$G$220,"") -> 78 | H17: =SUM(C17:G17) -> 78 | I17: =IFERROR(1-(G17/H17),"") -> 0
A18: Non-functional | B18: % | C18: =IFERROR(C17/$H17,"") -> 0 | D18: =IFERROR(D17/$H17,"") -> 0 | E18: =IFERROR(E17/$H17,"") -> 0 | F18: =IFERROR(F17/$H17,"") -> 0 | G18: =IFERROR(G17/$H17,"") -> 1 | H18: =SUM(C18:G18) -> 1 | I18: =I17 -> 0
A21: Table 3 - Online/Offline vs Level of Compliance
A22: Online/Offline | B22: Metric | C22: Fully Meets | D22: Meets through Configuration | E22: Customization Required | F22: Not Available | G22: No Response | H22: Total | I22: Response Rate %
A23: Online | B23: Count | C23: =COUNTIFS('Master Requirements Catalogue'!$A$13:$A$220,"<>",'Master Requirements Catalogue'!$H$13:$H$220,"Online",'Master Requirements Catalogue'!$G$13:$G$220,"Fully Meets") -> 0 | D23: =COUNTIFS('Master Requirements Catalogue'!$A$13:$A$220,"<>",'Master Requirements Catalogue'!$H$13:$H$220,"Online",'Master Requirements Catalogue'!$G$13:$G$220,"Meets through Configuration") -> 0 | E23: =COUNTIFS('Master Requirements Catalogue'!$A$13:$A$220,"<>",'Master Requirements Catalogue'!$H$13:$H$220,"Online",'Master Requirements Catalogue'!$G$13:$G$220,"Customization Required") -> 0 | F23: =COUNTIFS('Master Requirements Catalogue'!$A$13:$A$220,"<>",'Master Requirements Catalogue'!$H$13:$H$220,"Online",'Master Requirements Catalogue'!$G$13:$G$220,"Not Available") -> 0 | G23: =COUNTIFS('Master Requirements Catalogue'!$A$13:$A$220,"<>",'Master Requirements Catalogue'!$H$13:$H$220,"Online",'Master Requirements Catalogue'!$G$13:$G$220,"") -> 0 | H23: =SUM(C23:G23) -> 0 | I23: =IFERROR(1-(G23/H23),"")
A24: Online | B24: % | C24: =IFERROR(C23/$H23,"") | D24: =IFERROR(D23/$H23,"") | E24: =IFERROR(E23/$H23,"") | F24: =IFERROR(F23/$H23,"") | G24: =IFERROR(G23/$H23,"") | H24: =SUM(C24:G24) -> 0 | I24: =I23
A25: Offline | B25: Count | C25: =COUNTIFS('Master Requirements Catalogue'!$A$13:$A$220,"<>",'Master Requirements Catalogue'!$H$13:$H$220,"Offline",'Master Requirements Catalogue'!$G$13:$G$220,"Fully Meets") -> 0 | D25: =COUNTIFS('Master Requirements Catalogue'!$A$13:$A$220,"<>",'Master Requirements Catalogue'!$H$13:$H$220,"Offline",'Master Requirements Catalogue'!$G$13:$G$220,"Meets through Configuration") -> 0 | E25: =COUNTIFS('Master Requirements Catalogue'!$A$13:$A$220,"<>",'Master Requirements Catalogue'!$H$13:$H$220,"Offline",'Master Requirements Catalogue'!$G$13:$G$220,"Customization Required") -> 0 | F25: =COUNTIFS('Master Requirements Catalogue'!$A$13:$A$220,"<>",'Master Requirements Catalogue'!$H$13:$H$220,"Offline",'Master Requirements Catalogue'!$G$13:$G$220,"Not Available") -> 0 | G25: =COUNTIFS('Master Requirements Catalogue'!$A$13:$A$220,"<>",'Master Requirements Catalogue'!$H$13:$H$220,"Offline",'Master Requirements Catalogue'!$G$13:$G$220,"") -> 0 | H25: =SUM(C25:G25) -> 0 | I25: =IFERROR(1-(G25/H25),"")
A26: Offline | B26: % | C26: =IFERROR(C25/$H25,"") | D26: =IFERROR(D25/$H25,"") | E26: =IFERROR(E25/$H25,"") | F26: =IFERROR(F25/$H25,"") | G26: =IFERROR(G25/$H25,"") | H26: =SUM(C26:G26) -> 0 | I26: =I25
A27: Both | B27: Count | C27: =COUNTIFS('Master Requirements Catalogue'!$A$13:$A$220,"<>",'Master Requirements Catalogue'!$H$13:$H$220,"Both",'Master Requirements Catalogue'!$G$13:$G$220,"Fully Meets") -> 0 | D27: =COUNTIFS('Master Requirements Catalogue'!$A$13:$A$220,"<>",'Master Requirements Catalogue'!$H$13:$H$220,"Both",'Master Requirements Catalogue'!$G$13:$G$220,"Meets through Configuration") -> 0 | E27: =COUNTIFS('Master Requirements Catalogue'!$A$13:$A$220,"<>",'Master Requirements Catalogue'!$H$13:$H$220,"Both",'Master Requirements Catalogue'!$G$13:$G$220,"Customization Required") -> 0 | F27: =COUNTIFS('Master Requirements Catalogue'!$A$13:$A$220,"<>",'Master Requirements Catalogue'!$H$13:$H$220,"Both",'Master Requirements Catalogue'!$G$13:$G$220,"Not Available") -> 0 | G27: =COUNTIFS('Master Requirements Catalogue'!$A$13:$A$220,"<>",'Master Requirements Catalogue'!$H$13:$H$220,"Both",'Master Requirements Catalogue'!$G$13:$G$220,"") -> 0 | H27: =SUM(C27:G27) -> 0 | I27: =IFERROR(1-(G27/H27),"")
A28: Both | B28: % | C28: =IFERROR(C27/$H27,"") | D28: =IFERROR(D27/$H27,"") | E28: =IFERROR(E27/$H27,"") | F28: =IFERROR(F27/$H27,"") | G28: =IFERROR(G27/$H27,"") | H28: =SUM(C28:G28) -> 0 | I28: =I27
A29: No Response | B29: Count | C29: =COUNTIFS('Master Requirements Catalogue'!$A$13:$A$220,"<>",'Master Requirements Catalogue'!$H$13:$H$220,"",'Master Requirements Catalogue'!$G$13:$G$220,"Fully Meets") -> 0 | D29: =COUNTIFS('Master Requirements Catalogue'!$A$13:$A$220,"<>",'Master Requirements Catalogue'!$H$13:$H$220,"",'Master Requirements Catalogue'!$G$13:$G$220,"Meets through Configuration") -> 0 | E29: =COUNTIFS('Master Requirements Catalogue'!$A$13:$A$220,"<>",'Master Requirements Catalogue'!$H$13:$H$220,"",'Master Requirements Catalogue'!$G$13:$G$220,"Customization Required") -> 0 | F29: =COUNTIFS('Master Requirements Catalogue'!$A$13:$A$220,"<>",'Master Requirements Catalogue'!$H$13:$H$220,"",'Master Requirements Catalogue'!$G$13:$G$220,"Not Available") -> 0 | G29: =COUNTIFS('Master Requirements Catalogue'!$A$13:$A$220,"<>",'Master Requirements Catalogue'!$H$13:$H$220,"",'Master Requirements Catalogue'!$G$13:$G$220,"") -> 208 | H29: =SUM(C29:G29) -> 208 | I29: =IFERROR(1-(G29/H29),"") -> 0
A30: No Response | B30: % | C30: =IFERROR(C29/$H29,"") -> 0 | D30: =IFERROR(D29/$H29,"") -> 0 | E30: =IFERROR(E29/$H29,"") -> 0 | F30: =IFERROR(F29/$H29,"") -> 0 | G30: =IFERROR(G29/$H29,"") -> 1 | H30: =SUM(C30:G30) -> 1 | I30: =I29 -> 0
A33: Table 4 - Dependent on Other Systems vs Level of Compliance
A34: Dependent on other systems | B34: Metric | C34: Fully Meets | D34: Meets through Configuration | E34: Customization Required | F34: Not Available | G34: No Response | H34: Total | I34: Response Rate %
A35: Yes | B35: Count | C35: =COUNTIFS('Master Requirements Catalogue'!$A$13:$A$220,"<>",'Master Requirements Catalogue'!$I$13:$I$220,"Yes",'Master Requirements Catalogue'!$G$13:$G$220,"Fully Meets") -> 0 | D35: =COUNTIFS('Master Requirements Catalogue'!$A$13:$A$220,"<>",'Master Requirements Catalogue'!$I$13:$I$220,"Yes",'Master Requirements Catalogue'!$G$13:$G$220,"Meets through Configuration") -> 0 | E35: =COUNTIFS('Master Requirements Catalogue'!$A$13:$A$220,"<>",'Master Requirements Catalogue'!$I$13:$I$220,"Yes",'Master Requirements Catalogue'!$G$13:$G$220,"Customization Required") -> 0 | F35: =COUNTIFS('Master Requirements Catalogue'!$A$13:$A$220,"<>",'Master Requirements Catalogue'!$I$13:$I$220,"Yes",'Master Requirements Catalogue'!$G$13:$G$220,"Not Available") -> 0 | G35: =COUNTIFS('Master Requirements Catalogue'!$A$13:$A$220,"<>",'Master Requirements Catalogue'!$I$13:$I$220,"Yes",'Master Requirements Catalogue'!$G$13:$G$220,"") -> 0 | H35: =SUM(C35:G35) -> 0 | I35: =IFERROR(1-(G35/H35),"")
A36: Yes | B36: % | C36: =IFERROR(C35/$H35,"") | D36: =IFERROR(D35/$H35,"") | E36: =IFERROR(E35/$H35,"") | F36: =IFERROR(F35/$H35,"") | G36: =IFERROR(G35/$H35,"") | H36: =SUM(C36:G36) -> 0 | I36: =I35
A37: No | B37: Count | C37: =COUNTIFS('Master Requirements Catalogue'!$A$13:$A$220,"<>",'Master Requirements Catalogue'!$I$13:$I$220,"No",'Master Requirements Catalogue'!$G$13:$G$220,"Fully Meets") -> 0 | D37: =COUNTIFS('Master Requirements Catalogue'!$A$13:$A$220,"<>",'Master Requirements Catalogue'!$I$13:$I$220,"No",'Master Requirements Catalogue'!$G$13:$G$220,"Meets through Configuration") -> 0 | E37: =COUNTIFS('Master Requirements Catalogue'!$A$13:$A$220,"<>",'Master Requirements Catalogue'!$I$13:$I$220,"No",'Master Requirements Catalogue'!$G$13:$G$220,"Customization Required") -> 0 | F37: =COUNTIFS('Master Requirements Catalogue'!$A$13:$A$220,"<>",'Master Requirements Catalogue'!$I$13:$I$220,"No",'Master Requirements Catalogue'!$G$13:$G$220,"Not Available") -> 0 | G37: =COUNTIFS('Master Requirements Catalogue'!$A$13:$A$220,"<>",'Master Requirements Catalogue'!$I$13:$I$220,"No",'Master Requirements Catalogue'!$G$13:$G$220,"") -> 0 | H37: =SUM(C37:G37) -> 0 | I37: =IFERROR(1-(G37/H37),"")
A38: No | B38: % | C38: =IFERROR(C37/$H37,"") | D38: =IFERROR(D37/$H37,"") | E38: =IFERROR(E37/$H37,"") | F38: =IFERROR(F37/$H37,"") | G38: =IFERROR(G37/$H37,"") | H38: =SUM(C38:G38) -> 0 | I38: =I37
A39: No Response | B39: Count | C39: =COUNTIFS('Master Requirements Catalogue'!$A$13:$A$220,"<>",'Master Requirements Catalogue'!$I$13:$I$220,"",'Master Requirements Catalogue'!$G$13:$G$220,"Fully Meets") -> 0 | D39: =COUNTIFS('Master Requirements Catalogue'!$A$13:$A$220,"<>",'Master Requirements Catalogue'!$I$13:$I$220,"",'Master Requirements Catalogue'!$G$13:$G$220,"Meets through Configuration") -> 0 | E39: =COUNTIFS('Master Requirements Catalogue'!$A$13:$A$220,"<>",'Master Requirements Catalogue'!$I$13:$I$220,"",'Master Requirements Catalogue'!$G$13:$G$220,"Customization Required") -> 0 | F39: =COUNTIFS('Master Requirements Catalogue'!$A$13:$A$220,"<>",'Master Requirements Catalogue'!$I$13:$I$220,"",'Master Requirements Catalogue'!$G$13:$G$220,"Not Available") -> 0 | G39: =COUNTIFS('Master Requirements Catalogue'!$A$13:$A$220,"<>",'Master Requirements Catalogue'!$I$13:$I$220,"",'Master Requirements Catalogue'!$G$13:$G$220,"") -> 208 | H39: =SUM(C39:G39) -> 208 | I39: =IFERROR(1-(G39/H39),"") -> 0
A40: No Response | B40: % | C40: =IFERROR(C39/$H39,"") -> 0 | D40: =IFERROR(D39/$H39,"") -> 0 | E40: =IFERROR(E39/$H39,"") -> 0 | F40: =IFERROR(F39/$H39,"") -> 0 | G40: =IFERROR(G39/$H39,"") -> 1 | H40: =SUM(C40:G40) -> 1 | I40: =I39 -> 0
